Workbook

Sheet README
A1: Shea Resilience NPV Model: Tema factory and Tamale shea supply
A3: Purpose | B3: Compares climate-adaptation investments for a Tema (Free Zone) factory that buys crude shea butter from women processors around Tamale, refines it and makes cosmetics. Values are in constant 2026 USD; cedi-sourced figures were converted at GH₵11.55/USD.
A4: Case basis | B4: Case scenario built on market benchmarks, not company records: 200 t crude butter a year, bare baseline (no backup power, no insurance), 85% exports.
A5: How to use | B5: 1) Change blue cells on Inputs (Low/Base/High columns) or pick the case in column H. 2) Set the hazard scenario with G09. 3) Change the export share with G05. 4) Switch options on in Portfolio. 5) Read Results and Value chain.
A6: Colour code | B6: Blue text = input you can change · Black = formula · Green = link to another sheet · Yellow fill = key result or switch.
A7: Confidence tags | B7: Local field evidence = Ghana or primary market source · Transferable evidence = other countries or global data · Analyst assumption = reasoned estimate or design choice, editable. Every input carries its sources, the quoted figure, a rationale and a verdict (Confirmed / Adjusted / Unsupported / New).
A8: Key switches | B8: G09 hazard scenario (1 Benign, 2 Base, 3 Stress) · G05 export share · C11 margin basis (1 bulk benchmark, 2 value chain blend) · C12 share of butter sold as retail jars · G08 carbon revenue (0 in base) · N05 building insurance in baseline (0, bare) · P02 grant co-funding.
A9: Sheets | B9: Inputs · Hazards (damage curves, scenario values) · Value chain (where the jar price goes, share staying in Ghana) · Calc (derived quantities) · Supply (butter supply and loss by option) · Engine (cash flows by option) · Portfolio (combined package) · Results · Sensitivity (snapshot) · Checks · Gates · Source audit · Sources.
A10: Tax | B10: Free Zone: 0% corporate tax for G04a years, then 15% on exports and 25% on domestic income, blended by G05. Tax is applied to positive operating flow; capital allowances are ignored (small, conservative). Whether the 2.5% Growth & Sustainability Levy applies to Free Zone firms is not verified.
A11: Simplifications | B11: Backup power protects critical loads; production continues only in proportion to the load the battery (E06a) or genset (E25) covers. Option 8 models mango only; coconut rows are information for a later procurement option. Programme spend for supplier options is expensed. Portfolio uses a 20-year horizon for all options, so regeneration (which needs 30) is understated there. Supplier income is modelled for irrigation, apiaries and stoves only. Carbon is excluded unless G08 = 1.
A12: Limits to know | B12: Inputs that rest on reasoned estimates rather than sources include the Amazon FBA fee (check Amazon's Revenue Calculator), ocean freight (get a forwarder quote), the current US tariff on Ghana after 24 Jul 2026, retail price, flood depth at your site, and the programme effect sizes for fire, stoves and loyalty. Filter Inputs by 'Analyst assumption' to see them.
A13: Sensitivity sheet | B13: A snapshot computed by recalculating this workbook with each input at Low and High. It does not update live; recompute after major changes.

Sheet Inputs
A1: Input register: every number with its source, quoted figure, rationale and verdict
A2: Edit blue cells only. Column H picks the case (L = Low, B = Base, H = High) per input; hazard rows follow the scenario switch G09. Column I is the value the model uses.
A4: ID | B4: Group | C4: Input | D4: Unit | E4: Low | F4: Base | G4: High | H4: Case | I4: Active value | J4: Confidence tag | K4: Verdict | L4: Rationale | M4: Correction to earlier source | N4: Source 1 | O4: URL 1 | P4: Quoted figure 1 | Q4: Source 2 | R4: URL 2 | S4: Quoted figure 2 | T4: Source 3 | U4: URL 3 | V4: Quoted figure 3
A5: G01 | B5: Global | C5: Discount rate, real USD | D5: % | E5: 0.09 | F5: 0.13 | G5: 0.17 | H5: B | I5: =IF(H5="L",E5,IF(H5="H",G5,F5)) -> 0.13 | J5: Transferable evidence | K5: Adjusted | L5: Cost of equity = 5.24% US 10-yr + 4.23% mature-market premium + 9.71% Ghana country premium = 19.2% nominal, 16.4% real (10-yr breakeven inflation 2.36%). With 40% local debt at ~7.5% real, WACC ≈ 12.8%. Low case: concessional debt and a rating upgrade; high case: all-equity SME premium. | M5: Previous 8/12/16 used an older risk-free rate. Fitch upgraded Ghana to B in May 2026, so the country premium may fall. | N5: Damodaran, Jan 2026 | O5: https://pages.stern.nyu.edu/~adamodar/New_Home_Page/datafile/ctryprem.html | P5: Ghana | Caa1 | 6.37% | 9.71% | 13.94% | Q5: FRED DGS10, 1 Oct 2026 | R5: https://fred.stlouisfed.org/series/DGS10 | S5: 2026-10-01: 5.24 | T5: Graphic, 8 May 2026 | U5: https://www.graphic.com.gh/business/business-news/fitch-upgrades-ghanas-sovereign-rating-as-debt-burden-eases.html | V5: upgraded … from 'B-' to 'B'
A6: G02a | B6: Global | C6: Horizon, plant options | D6: years | E6: 20 | F6: 20 | G6: 20 | H6: B | I6: =IF(H6="L",E6,IF(H6="H",G6,F6)) -> 20 | J6: Transferable evidence | K6: Confirmed | L6: 20 years matches standard appraisal practice for plant. Tree measures need 30+ years because benefits start late; 40 years is a sensitivity. | N6: ADB project appraisal guidance | O6: https://development.asia/summary/guidelines-economic-analysis-projects | P6: normally spans over 20–30 years | Q6: ICRAF species profile | R6: https://apps.worldagroforestry.org/treedb2/speciesprofile.php?Spid=394 | S6: trees do not start to bear fruit until they are 15-20 years old
A7: G02b | B7: Global | C7: Horizon, tree options | D7: years | E7: 30 | F7: 30 | G7: 30 | H7: B | I7: =IF(H7="L",E7,IF(H7="H",G7,F7)) -> 30 | J7: Transferable evidence | K7: Confirmed | L7: 20 years matches standard appraisal practice for plant. Tree measures need 30+ years because benefits start late; 40 years is a sensitivity. | N7: ADB project appraisal guidance | O7: https://development.asia/summary/guidelines-economic-analysis-projects | P7: normally spans over 20–30 years | Q7: ICRAF species profile | R7: https://apps.worldagroforestry.org/treedb2/speciesprofile.php?Spid=394 | S7: trees do not start to bear fruit until they are 15-20 years old
A8: G03 | B8: Global | C8: Exchange rate (info only) | D8: GH₵/USD | E8: 10.5 | F8: 11.6 | G8: 14.5 | H8: B | I8: =IF(H8="L",E8,IF(H8="H",G8,F8)) -> 11.6 | J8: Local field evidence | K8: Adjusted | L8: Model runs in USD; FX converts cedi-priced inputs. The cedi moved from ~16 to ~10 within 2025, so the high case is widened to 14.5. | N8: MyJoyOnline/BoG, Sep 2026 | O8: https://www.myjoyonline.com/cedi-depreciates-by-9-5-in-nine-months-of-2026-bog/ | P8: GH¢11.55 interbank | Q8: Databank, 16 Sep 2026 | R8: https://www.myjoyonline.com/cedi-to-end-year-at-gh%C2%A212-20-to-a-us-dollar-databank-research/ | S8: GH¢12.20 at end-2026 | T8: Barclays via Reuters, Jul 2025 | U8: https://www.marketscreener.com/quote/stock/BARCLAYS-PLC-9583556/news/Ghana-s-cedi-set-to-weaken-sharply-as-gold-exports-plateau-and-spending-rises-Barclays-warns-50499015/ | V8: 14.5 per dollar by end-2026
A9: G04a | B9: Global | C9: Free Zone tax holiday | D9: years | E9: 10 | F9: 10 | G9: 10 | H9: B | I9: =IF(H9="L",E9,IF(H9="H",G9,F9)) -> 10 | J9: Local field evidence | K9: Adjusted | L9: Your factory is a Free Zone enterprise: 0% for years 1–10, then 15% on export income and 25% on domestic sales. Spot-checked against PwC. Whether the 2.5% Growth & Sustainability Levy applies to Free Zone firms is unresolved. | M9: Previous model used a flat 25%. The ordinary agro-processing regime (5% for 5 years, then 20% in Tema) is kept as an alternative scenario. | N9: PwC Tax Summaries, Mar 2026 | O9: https://taxsummaries.pwc.com/Ghana/Corporate/Tax-credits-and-incentives | P9: do not pay CIT for the first ten years … 15% … export … 25% | Q9: PwC Tax Summaries | R9: https://taxsummaries.pwc.com/ghana/corporate/taxes-on-corporate-income | S9: The general corporate income tax (CIT) rate is 25%.
A10: G04b | B10: Global | C10: CIT on export income after holiday | D10: % | E10: 0.15 | F10: 0.15 | G10: 0.15 | H10: B | I10: =IF(H10="L",E10,IF(H10="H",G10,F10)) -> 0.15 | J10: Local field evidence | K10: Adjusted | L10: Your factory is a Free Zone enterprise: 0% for years 1–10, then 15% on export income and 25% on domestic sales. Spot-checked against PwC. Whether the 2.5% Growth & Sustainability Levy applies to Free Zone firms is unresolved. | M10: Previous model used a flat 25%. The ordinary agro-processing regime (5% for 5 years, then 20% in Tema) is kept as an alternative scenario. | N10: PwC Tax Summaries, Mar 2026 | O10: https://taxsummaries.pwc.com/Ghana/Corporate/Tax-credits-and-incentives | P10: do not pay CIT for the first ten years … 15% … export … 25% | Q10: PwC Tax Summaries | R10: https://taxsummaries.pwc.com/ghana/corporate/taxes-on-corporate-income | S10: The general corporate income tax (CIT) rate is 25%.
A11: G04c | B11: Global | C11: CIT on domestic income after holiday | D11: % | E11: 0.25 | F11: 0.25 | G11: 0.25 | H11: B | I11: =IF(H11="L",E11,IF(H11="H",G11,F11)) -> 0.25 | J11: Local field evidence | K11: Adjusted | L11: Your factory is a Free Zone enterprise: 0% for years 1–10, then 15% on export income and 25% on domestic sales. Spot-checked against PwC. Whether the 2.5% Growth & Sustainability Levy applies to Free Zone firms is unresolved. | M11: Previous model used a flat 25%. The ordinary agro-processing regime (5% for 5 years, then 20% in Tema) is kept as an alternative scenario. | N11: PwC Tax Summaries, Mar 2026 | O11: https://taxsummaries.pwc.com/Ghana/Corporate/Tax-credits-and-incentives | P11: do not pay CIT for the first ten years … 15% … export … 25% | Q11: PwC Tax Summaries | R11: https://taxsummaries.pwc.com/ghana/corporate/taxes-on-corporate-income | S11: The general corporate income tax (CIT) rate is 25%.
A12: G05 | B12: Global | C12: Export share of sales | D12: % | E12: 0.7 | F12: 0.85 | G12: 1 | H12: B | I12: =IF(H12="L",E12,IF(H12="H",G12,F12)) -> 0.85 | J12: Analyst assumption | K12: New | L12: Sets the blended tax rate after year 10. Free Zone firms are export-oriented; the minimum export share was not verified on a GFZA page, so confirm with GFZA. | N12: PwC Tax Summaries | O12: https://taxsummaries.pwc.com/Ghana/Corporate/Tax-credits-and-incentives | P12: 15% … export … 25%
A13: G06 | B13: Global | C13: Capital allowance, plant (info only) | D13: % RB | E13: 0.3 | F13: 0.3 | G13: 0.3 | H13: B | I13: =IF(H13="L",E13,IF(H13="H",G13,F13)) -> 0.3 | J13: Local field evidence | K13: Confirmed | L13: Only affects years 11+ because the first 10 years are tax-free. The engine taxes positive operating benefit after year 10 and ignores allowances, a small conservative simplification. | N13: PwC Deductions | O13: https://taxsummaries.pwc.com/ghana/corporate/deductions | P13: plant and machinery used in manufacturing … 30% reducing balance
A14: G07 | B14: Global | C14: Supply-shock correlation, shea vs mango/coconut | D14: ρ | E14: 0 | F14: 0.3 | G14: 0.8 | H14: B | I14: =IF(H14="L",E14,IF(H14="H",G14,F14)) -> 0.3 | J14: Analyst assumption | K14: Adjusted | L14: No yield-correlation study exists. Opposite rainfall trends argue for low correlation; a shared El Niño/La Niña driver argues for a fat upper tail. No rainfall or yield series could be downloaded this session (NASA POWER blocked to automated access), so the range is a reasoned estimate. | M14: Previous base of 0.5 had no source; the KNUST study reports trends, not correlations. | N14: Atiah et al. 2019, KNUST | O14: https://ir.knust.edu.gh/items/55b8fbe9-58e6-4ed9-aedf-281400004a58/full | P14: decreasing trends of consecutive wet days … over the Savannah … increasing trends dominate the Forest zone | Q14: Baidu 2016, KNUST | R14: https://ir.knust.edu.gh/items/3dfcb635-4563-4fad-9e72-aba3d0115d5c/full | S14: effects of strong El Niño and La Niña episodes on the region
A15: C01 | B15: Company | C15: Crude shea butter purchased | D15: t/yr | E15: 100 | F15: 200 | G15: 500 | H15: B | I15: =IF(H15="L",E15,IF(H15="H",G15,F15)) -> 200 | J15: Analyst assumption | K15: New | L15: Case benchmark for a small/medium refiner-formulator. 200 t butter ≈ 540 t kernel at 37% yield ≈ 0.4% of national nut output. Savannah Fruits, a larger exporter, ships 10–12 containers a month. | N15: GNA, Sep 2026 | O15: https://gna.org.gh/2026/09/vice-president-opoku-agyemang-opens-world-shea-expo-2026-in-tamale/ | P15: 130,000 to 150,000 metric tonnes | Q15: Ajala et al. 2019 | R15: https://doaj.org/article/73e0ffab0b6a4dd882aaedcc6ee0e28b | S15: The optimum 37% (w/w) yield | T15: How We Made It In Africa | U15: https://www.howwemadeitinafrica.com/ghana-company-sells-homegrown-shea-butter-to-unilever-and-loccitane/139951/ | V15: 10 to 12 containers every month
A16: C02 | B16: Company | C16: Crude butter purchase price | D16: USD/kg | E16: 2 | F16: 2.8 | G16: 4.7 | H16: B | I16: =IF(H16="L",E16,IF(H16="H",G16,F16)) -> 2.8 | J16: Local field evidence | K16: New | L16: Kernel at the TCDA minimum (~USD 780/t) ÷ 0.37 yield ≈ USD 2.1/kg in kernel cost alone; add processing and margin for ~2.8. Tridge has only 5 Ghana transactions (1.75–4.69). | M16: TCDA price dates from the 2025 season; no 2026/27 price found. | N16: Graphic, TCDA, Jul 2025 | O16: https://www.graphic.com.gh/business/business-news/tcda-sets-gh-9-01-kg-as-minimum-producer-price-for-shea-nuts-from-july-1.html | P16: GH₵9.01 per kilogram | Q16: Ajala et al. 2019 | R16: https://doaj.org/article/73e0ffab0b6a4dd882aaedcc6ee0e28b | S16: 37% (w/w) yield | T16: Tridge Ghana export samples, 2026 | U16: https://www.tridge.com/intelligences/shea-butter/GH/price | V16: 1.75 … 3.26 … 4.69 USD/kg
A17: C03 | B17: Company | C17: Contribution margin per t crude butter | D17: USD/t | E17: 800 | F17: 1500 | G17: 3000 | H17: B | I17: =IF(H17="L",E17,IF(H17="H",G17,F17)) -> 1500 | J17: Transferable evidence | K17: New | L17: Refined bulk butter sells for ~USD 4.7–6.0/kg against ~2.8 crude, leaving ~1.0–2.5/kg before refining cost. Cosmetic finished goods earn more, but no cosmetic price source was opened, so the high case is an assumption. | N17: Tridge refined shea butter, Apr 2026 | O17: https://www.tridge.com/market-overview/refined-shea-butter | P17: India 5.99, Netherlands 5.76, France 4.70 USD/kg | Q17: Tridge Ghana crude samples | R17: https://www.tridge.com/intelligences/shea-butter/GH/price | S17: 1.75–4.69 USD/kg
A18: C04 | B18: Company | C18: Replacement premium in a short year | D18: USD/t butter | E18: 400 | F18: 675 | G18: 1100 | H18: B | I18: =IF(H18="L",E18,IF(H18="H",G18,F18)) -> 675 | J18: Transferable evidence | K18: Derived | L18: Per-kernel premium of USD 150/250/400 (a 27–40% shortage-year price rise plus extra haulage) × 2.7 t kernel per t butter. | N18: Gulf Times/AFP, Dec 2025 | O18: https://www.gulf-times.com/article/717500/international/africa/sellers-under-strain-in-ivory-coasts-struggling-shea-industry | P18: 250 CFA francs to 350 CFA per kilogram | Q18: IFDC Tema port fact sheet, 2019 | R18: https://ifdc.org/wp-content/uploads/2020/09/EnGRAIS_Port-Fact-Sheet-Tema_EN.pdf | S18: Road transit (Tema→Bobo-Dioulasso) 60 USD/t
A19: C05 | B19: Company | C19: Unreplaceable share of a shortfall | D19: % | E19: 0.15 | F19: 0.3 | G19: 0.6 | H19: B | I19: =IF(H19="L",E19,IF(H19="H",G19,F19)) -> 0.3 | J19: Analyst assumption | K19: Unsupported | L19: No literature measures this. The Côte d'Ivoire 2025 anecdote (a buyer ~85% short) justifies a fat high case. | N19: Gulf Times/AFP, Dec 2025 | O19: https://www.gulf-times.com/article/717500/international/africa/sellers-under-strain-in-ivory-coasts-struggling-shea-industry | P19: normally … 3,500 and 4,000 tons … haven't even managed 500 tons
A20: C06 | B20: Company | C20: Catchment supply ÷ requirement | D20: ratio | E20: 1 | F20: 1.25 | G20: 2 | H20: B | I20: =IF(H20="L",E20,IF(H20="H",G20,F20)) -> 1.25 | J20: Analyst assumption | K20: Adjusted | L20: Only ~40% of available nuts are collected nationally, so suppliers can usually find more; the ratio sets when structural decline turns into a deficit. | N20: Citi Newsroom, Jul 2025 | O20: https://www.citinewsroom.com/2025/07/ghana-targets-640m-annual-revenue-from-shea-under-24-hour-economy-push/ | P20: 40% of the available shea nut resource is recovered
A21: C07 | B21: Company | C21: Assets + inventory at Tema | D21: USD | E21: 1000000 | F21: 1800000 | G21: 3000000 | H21: B | I21: =IF(H21="L",E21,IF(H21="H",G21,F21)) -> 1800000 | J21: Analyst assumption | K21: Confirmed | L21: No direct benchmark for a refiner-formulator; the range sits between community centres and industrial plants. Replace with your asset register. | N21: Graphic, 2019 | O21: https://www.graphic.com.gh/news/general-news/ghana-news-shea-butter-processing-facility-inaugurated-at-kpugi.html | P21: US$75,000 community centre | Q21: Ecofin, Jul 2025 | R21: https://www.ecofinagency.com/news/2307-47810-ghana-to-revive-shea-processing-plant-with-4-million-injection | S21: €4M rehabilitation of Buipe | T21: AllAfrica, Feb 2026 | U21: https://allafrica.com/stories/202602110580.html | V21: US$90 million AAK factory
A22: C08 | B22: Company | C22: Electricity use | D22: MWh/yr | E22: 75 | F22: 250 | G22: 600 | H22: B | I22: =IF(H22="L",E22,IF(H22="H",G22,F22)) -> 250 | J22: Transferable evidence | K22: Adjusted | L22: Heat dominates shea processing and is usually biomass or steam; electricity covers motors, vacuum, refining pumps, cold store and HVAC. | M22: Previous 350 MWh implied electric heating. | N22: Nounagnon et al. 2024 | O22: https://ideas.repec.org/a/spr/envsyd/v44y2024i1d10.1007_s10669-023-09925-y.html | P22: 8–10 kWh of heat per kg of produced crude shea butter | Q22: Carré & Quinsac 2011 | R22: https://www.gcirc.org/fileadmin/documents/Proceedings/IRCPrague2011vol2/Oilmill_Refining_Process/1101-1104.pdf | S22: 28.4 kWh of electric power … per ton of seeds
A23: C09 | B23: Company | C23: Operating hours per day | D23: h | E23: 8 | F23: 16 | G23: 24 | H23: B | I23: =IF(H23="L",E23,IF(H23="H",G23,F23)) -> 16 | J23: Analyst assumption | K23: New | L23: Sets how many outage hours hit production. Two shifts is the base for a small refiner.
A24: C10 | B24: Company | C24: Lost output not recovered later | D24: % | E24: 0.3 | F24: 0.5 | G24: 0.8 | H24: B | I24: =IF(H24="L",E24,IF(H24="H",G24,F24)) -> 0.5 | J24: Transferable evidence | K24: New | L24: Part of the output lost in an outage or flood is caught up later; the rest is lost margin. Cross-check: total outage loss should land within the 0–10% of sales band firms report. | N24: World Bank Enterprise Survey Ghana 2023 | O24: https://microdata.worldbank.org/catalog/6444 | P24: losses as % of annual sales: 28.6% report 0, 12.6% report 5%, 11.3% report 10%
A25: H01 | B25: Hazards | C25: Probability of a poor shea year | D25: /yr | E25: 0.15 | F25: 0.3 | G25: 0.5 | H25: =CHOOSE(in_G09,"L","B","H") -> B | I25: =IF(H25="L",E25,IF(H25="H",G25,F25)) -> 0.3 | J25: Transferable evidence | K25: Adjusted | L25: 'Every 2–3 years' describes one tree. Trees fruit under 50% in sync, so a supply-wide bad year is rarer. Drier conditions raise variability, which supports a 0.5 high case. | N25: FAO, Boffa 1999 | O25: https://www.fao.org/4/X3940E/X3940E09.htm | P25: varied by a factor of five in two consecutive years | Q25: Bondé et al. 2019, Burkina | R25: https://agris.fao.org/search/fr/records/65df45000f3e94b9e5d6cd8e | S25: interannual variation … higher in drier climatic conditions | T25: GMet State of the Climate 2025 | U25: https://www.meteo.gov.gh/documents/12579/State_of_the_climate_Report_2025.pdf | V25: Tamale recorded the longest dry spell with a maximum of 13 consecutive dry days
A26: H02 | B26: Hazards | C26: Shortfall in a poor year | D26: % | E26: 0.2 | F26: 0.3 | G26: 0.5 | H26: =CHOOSE(in_G09,"L","B","H") -> B | I26: =IF(H26="L",E26,IF(H26="H",G26,F26)) -> 0.3 | J26: Analyst assumption | K26: Confirmed | L26: Stand-level swings are large but average out across a catchment. No usable national series exists (FAOSTAT Ghana looks imputed). | N26: FAO, Boffa 1999 | O26: https://www.fao.org/4/X3940E/X3940E09.htm | P26: varied by a factor of five | Q26: Ecofin, Jul 2025 | R26: https://www.ecofinagency.com/news-agriculture/1607-47708-shea-sector-west-africa-market-struggles-as-export-bans-expand | S26: two years of reduced harvests
A27: H03 | B27: Hazards | C27: Fire share of the poor-year shortfall | D27: % | E27: 0.1 | F27: 0.3 | G27: 0.5 | H27: B | I27: =IF(H27="L",E27,IF(H27="H",G27,F27)) -> 0.3 | J27: Analyst assumption | K27: Adjusted | L27: Late fires hit flowering, but early fires can raise yield, and pollination and drought compete as causes. No study quantifies the fire share. | M27: Previous citation 'Husseini et al.' was wrong (first author Dahan), and its 825 km²/yr, 19,811 km² and 60% figures are internally inconsistent and unusable. | N27: Lamien et al. 2004 | O27: https://revues.cirad.fr/index.php/fruits/article/download/35862/34641/37906 | P27: late fires … coincide with shea flowering peaks and could harm resulting fruit production | Q27: FAO, Boffa 1999 | R27: https://www.fao.org/4/X3940E/X3940E09.htm | S27: a light, early fire … lead to higher fruit production | T27: Dahan, Kasei & Husseini 2023 | U27: https://link.springer.com/10.1186/s42408-023-00198-z | V27: Fire activity started in October and peaked in December
A28: H04 | B28: Hazards | C28: Structural tree-loss decline | D28: %/yr | E28: 0.005 | F28: 0.015 | G28: 0.025 | H28: =CHOOSE(in_G09,"L","B","H") -> B | I28: =IF(H28="L",E28,IF(H28="H",G28,F28)) -> 0.015 | J28: Transferable evidence | K28: Adjusted | L28: 8M ÷ 500M = 1.6%/yr. The 5,000 ha figure implies only 0.06%/yr across Ghana's shea zone. The 8M figure is an advocacy estimate with no published method. | M28: '9.4 million trees in Ghana' is wrong (it also claims they yield 100 t of nuts). UN-REDD '77% loss' is forest cover, not shea. | N28: GSA via MyJoyOnline, Jul 2026 | O28: https://www.myjoyonline.com/west-africa-losing-8-million-shea-trees-annually-global-shea-alliance-warns/ | P28: 8 million trees annually | Q28: Bup et al. 2014, OCL | R28: https://www.ocl-journal.org/articles/ocl/pdf/2014/02/ocl130026.pdf | S28: About 500 million shea trees grow in Africa | T28: AllAfrica, Jun 2025 | U28: https://allafrica.com/stories/202506110147.html | V28: 5,000 hectares of shea trees annually
A29: H05 | B29: Hazards | C29: Probability the Tema site floods | D29: /yr | E29: 0.05 | F29: 0.1 | G29: 0.25 | H29: =CHOOSE(in_G09,"L","B","H") -> B | I29: =IF(H29="L",E29,IF(H29="H",G29,F29)) -> 0.1 | J29: Local field evidence | K29: Adjusted | L29: Parts of Tema flooded in 2010, 2017, May 2025 and twice in June 2026, including the VALCO/Sentuo industrial zone. Site-level probability depends on elevation, so the high case is raised. | N29: MyJoyOnline, Jun 2010 | O29: https://www.myjoyonline.com/?p=10047971 | P29: bodies of 11 people who drowned in Tema | Q29: Ghana Armed Forces, Jun 2026 | R29: https://www.gafonline.mil.gh/blog-details/eastern-naval-command-conducts-flood-rescues-in-tema | S29: Waterland, VALCO/Sentuo, Tema New Town, Afienya and Alajo | T29: StarrFM/NADMO, May 2025 | U29: https://starrfm.com.gh/may-18-floods-most-severe-in-5-years-in-parts-of-ghana-nadmo | V29: Tema among affected areas
A30: H06 | B30: Hazards | C30: Flood depth without measures | D30: m | E30: 0.3 | F30: 0.5 | G30: 1 | H30: =CHOOSE(in_G09,"L","B","H") -> B | I30: =IF(H30="L",E30,IF(H30="H",G30,F30)) -> 0.5 | J30: Analyst assumption | K30: Adjusted | L30: No public depth exists for any Tema flood. 0.5 m (knee to thigh height) is a reasoned base for an industrial site flooded by overland flow; 1.0 m covers a low-lying parcel. Replace with a site survey: on the JRC curve damage rises from ~4% at 0.3 m to ~25% at 1.0 m. | N30: JRC depth-damage report | O30: https://publications.jrc.ec.europa.eu/repository/handle/JRC105688 | P30: no Tema depth data
A31: H07 | B31: Hazards | C31: Downtime per flood | D31: days | E31: 2 | F31: 5 | G31: 10 | H31: B | I31: =IF(H31="L",E31,IF(H31="H",G31,F31)) -> 5 | J31: Local field evidence | K31: Confirmed | L31: Tema Shipyard reopened ~9 days after the 29 Jun 2026 flood, with partial operation in between. | N31: Citi Newsroom, Jul 2026 | O31: https://www.citinewsroom.com/?p=1369423 | P31: We shall be back to business on Wednesday | Q31: Amegayie 2022, Tema survey | R31: https://www.etd.ceu.edu/2022/amegayie_amos.pdf | S31: 52.4% … hours, 33.6% … days, 9.2% … weeks
A32: H08 | B32: Hazards | C32: Grid outage hours | D32: h/yr | E32: 50 | F32: 250 | G32: 1100 | H32: =CHOOSE(in_G09,"L","B","H") -> B | I32: =IF(H32="L",E32,IF(H32="H",G32,F32)) -> 250 | J32: Local field evidence | K32: Adjusted | L32: Normal years ~50–70 h (WBES); 2016 dumsor ~720 h; 2024 survey implies up to ~1,100 h. Base blends normal years with a crisis roughly one year in four. | M32: Previous high of 1,500 h exceeded every observed crisis year. | N32: World Bank Enterprise Survey 2023 | O32: https://microdata.worldbank.org/catalog/6444 | P32: modal 2 outages per month | Q32: GNA / IEA Ghana, Jun 2024 | R32: https://gna.org.gh/2024/06/accra-residents-experience-outages-four-times-a-week-iea-survey/ | S32: 75.4 per cent … at least thrice a week | T32: Energy for Growth Hub | U32: https://energyforgrowth.org/article/how-can-small-and-medium-enterprises-cope-with-power-outages | V32: about 10 outages in a month … about 6 hours
A33: H09 | B33: Hazards | C33: Depth-damage curve (1 = Africa, 2 = Global) | D33: switch | E33: 1 | F33: 1 | G33: 2 | H33: B | I33: =IF(H33="L",E33,IF(H33="H",G33,F33)) -> 1 | J33: Transferable evidence | K33: Confirmed | L33: Values spot-checked. The Africa curve rests on one South African function, so the global curve (29.7% at 0.5 m) is the high case. | N33: JRC data via os-climate | O33: https://raw.githubusercontent.com/os-climate/physrisk/main/docs/user_guide/vulnerability/vulnerability_functions/inundation_jrc/raw.csv | P33: Africa_Mean 0.5 m 0.0627; 1.0 m 0.2472 | Q33: Huizinga et al. 2017, JRC | R33: https://publications.jrc.ec.europa.eu/repository/handle/JRC105688 | S33: only one function for the class 'Industry' … originating from South Africa
A34: I01 | B34: 1 Irrigation | C34: Solar borehole system, turnkey | D34: USD | E34: 10000 | F34: 27700 | G34: 35000 | H34: B | I34: =IF(H34="L",E34,IF(H34="H",G34,F34)) -> 27700 | J34: Local field evidence | K34: Adjusted | L34: GH¢8M ÷ 25 = GH¢320k ≈ USD 27.7k each, including storage and delivery. A plot-scale kit (borehole + 1-acre pump + tank) can cost ~USD 5–10k. | M34: Agrilinks USD figures used an older exchange rate; at GH¢11.55 the pump is USD 2.2–2.6k. | N34: ISD Ghana, GROW2 | O34: https://www.isd.gov.gh/government-builds-25-solar-boreholes-to-boost-vegetable-production-in-northern-ghana/ | P34: 25 modern solar powered boreholes … about GH¢8 million | Q34: Agrilinks/IWMI | R34: https://agrilinks.org/post/cocoa-farmers-ghana-show-strong-interest-solar-based-irrigation-pump-costs-are-often-too-high | S34: GHS 25,000 … and GHS 30,000 … at least one acre
A35: I02 | B35: 1 Irrigation | C35: Borehole success rate | D35: % | E35: 0.3 | F35: 0.45 | G35: 0.65 | H35: B | I35: =IF(H35="L",E35,IF(H35="H",G35,F35)) -> 0.45 | J35: Local field evidence | K35: Adjusted | L35: BGS defines success at hand-pump yield; irrigation needs more water, so rates are shifted down. | N35: BGS/UNICEF, Northern Region | O35: https://core.ac.uk/display/385054 | P35: typically between 40 and 60%, but range from 20% … to around 70%
A36: I03 | B36: 1 Irrigation | C36: Systems installed | D36: count | E36: 2 | F36: 4 | G36: 8 | H36: B | I36: =IF(H36="L",E36,IF(H36="H",G36,F36)) -> 4 | J36: Analyst assumption | K36: Confirmed | L36: Programme design choice; budget ~2.2 drilling attempts per working system.
A37: I04 | B37: 1 Irrigation | C37: Garden net income per system | D37: USD/yr | E37: 1000 | F37: 2500 | G37: 5000 | H37: B | I37: =IF(H37="L",E37,IF(H37="H",G37,F37)) -> 2500 | J37: Local field evidence | K37: Adjusted | L37: About 1 ha per system. 2026 gross margins (~USD 1.2k/ha) are well below 2017 USD figures. Accrues to the farmer account. | M37: Area per GROW2 system is contradictory (50 acres each vs 50 acres in total). | N37: FSRP Ghana, Aug 2026 | O37: https://fsrp.org.gh/blog/From-Dry-Fields-To-Full-Baskets-%28How-Ghana%27s-Tomato-Farmers-Are-Re-writting-The-Dry-Season%29 | P37: GHS 14,150 per hectare | Q37: IWMI/ILSSI 2017 | R37: https://borlaug.tamu.edu/wp-content/uploads/sites/3/2019/11/ilssi-technical-report-economic-analayis-ghana.pdf | S37: GHS 19,249/ha (USD 4,466/ha)
A38: I05 | B38: 1 Irrigation | C38: Loyalty: cut in poor-year loss among served suppliers | D38: pts | E38: 0 | F38: 0.05 | G38: 0.15 | H38: B | I38: =IF(H38="L",E38,IF(H38="H",G38,F38)) -> 0.05 | J38: Analyst assumption | K38: Unsupported | L38: Qualitative evidence only. AAK's obligation-free pre-finance to 275,000 women competes for the same supply, so the low case is zero. | N38: GSA finance pilot | O38: https://globalshea.com/gsamain/storage/img/news/docs/Finance%20Reimagined_%20A%20Replicable%20Model%20For%20Financing%20The%20Shea%20Industry%20(1).pdf | P38: reduced and in most cases, eliminated side-selling | Q38: Graphic, AAK 2026 | R38: https://www.graphic.com.gh/news/general-news/ghanan-news-disbursement-for-shea-collectors-begins-in-bimbilla-275-000-women-to-receive-eur13m-for-2026-season.html | S38: obligation-free … not obligated to sell
A39: I06 | B39: 1 Irrigation | C39: Seedling survival gain with watering | D39: pts | E39: 0.1 | F39: 0.2 | G39: 0.3 | H39: B | I39: =IF(H39="L",E39,IF(H39="H",G39,F39)) -> 0.2 | J39: Transferable evidence | K39: Confirmed | L39: Applies only when irrigation is paired with Option 3 nurseries. | N39: Noulekoun et al., Benin | O39: https://www.tropentag.de/2016/abstracts/pdf/1029.pdf | P39: reduced by ten-folds the mortality rate of … Parkia biglobosa
A40: I07 | B40: 1 Irrigation | C40: O&M | D40: % capex/yr | E40: 0.01 | F40: 0.02 | G40: 0.03 | H40: B | I40: =IF(H40="L",E40,IF(H40="H",G40,F40)) -> 0.02 | J40: Analyst assumption | K40: Unsupported | L40: Typical for solar pumping; no Ghana source found.
A41: A01 | B41: 2 Apiaries | C41: Hive, kit and training | D41: USD/hive | E41: 65 | F41: 100 | G41: 150 | H41: B | I41: =IF(H41="L",E41,IF(H41="H",G41,F41)) -> 100 | J41: Transferable evidence | K41: Confirmed | L41: Local top-bar box USD 20–40, shared protective kit and training. The 2017 GH¢750 converted at 2017 rates is ~USD 170, so the low case is optimistic. | N41: Bee Culture, Feb 2017 | O41: https://www.beeculture.com/catch-buzz-ghana-wants-piece-global-honey-export-business-intends-fund-growth/ | P41: cost of one beehive, other inputs and training at GH¢750 | Q41: Rufford, Bia, 2015 | R41: https://media.rufford.org/media/project_reports/12807-1%20Final%20Report.pdf | S41: £13.50 per hive
...

Sheet Hazards
A1: Flood depth-damage curves, industrial buildings (JRC, Huizinga et al. 2017)
A2: Share of asset value damaged by depth. Africa curve = Low/Base; Global curve = High (switch H09). Source: os-climate/physrisk copy of JRC data, spot-checked.
A4: Depth (m) | B4: Africa industrial | C4: Global industrial
A5: 0 | B5: 0 | C5: 0
A6: 0.5 | B6: 0.0627 | C6: 0.297
A7: 1 | B7: 0.2472 | C7: 0.48
A8: 1.5 | B8: 0.4033 | C8: 0.603
A9: 2 | B9: 0.4945 | C9: 0.694
A10: 3 | B10: 0.6847 | C10: 0.82
A12: Sources: https://raw.githubusercontent.com/os-climate/physrisk/main/docs/user_guide/vulnerability/vulnerability_functions/inundation_jrc/raw.csv
A13: https://publications.jrc.ec.europa.eu/repository/handle/JRC105688
A15: Scenario values used for hazard inputs (Inputs column E = Benign, F = Base, G = Stress):
A16: Input | B16: Benign | C16: Base | D16: Stress
A17: =Inputs!A25&" "&Inputs!C25 -> H01 Probability of a poor shea year | B17: =Inputs!E25 -> 0.15 | C17: =Inputs!F25 -> 0.3 | D17: =Inputs!G25 -> 0.5
A18: =Inputs!A26&" "&Inputs!C26 -> H02 Shortfall in a poor year | B18: =Inputs!E26 -> 0.2 | C18: =Inputs!F26 -> 0.3 | D18: =Inputs!G26 -> 0.5
A19: =Inputs!A28&" "&Inputs!C28 -> H04 Structural tree-loss decline | B19: =Inputs!E28 -> 0.005 | C19: =Inputs!F28 -> 0.015 | D19: =Inputs!G28 -> 0.025
A20: =Inputs!A29&" "&Inputs!C29 -> H05 Probability the Tema site floods | B20: =Inputs!E29 -> 0.05 | C20: =Inputs!F29 -> 0.1 | D20: =Inputs!G29 -> 0.25
A21: =Inputs!A30&" "&Inputs!C30 -> H06 Flood depth without measures | B21: =Inputs!E30 -> 0.3 | C21: =Inputs!F30 -> 0.5 | D21: =Inputs!G30 -> 1
A22: =Inputs!A32&" "&Inputs!C32 -> H08 Grid outage hours | B22: =Inputs!E32 -> 50 | C22: =Inputs!F32 -> 250 | D22: =Inputs!G32 -> 1100

Sheet Value chain
A1: Value chain: where the price of one jar goes, and how much stays in Ghana
A2: One 8 oz (227 g) shea body butter jar. Export channel = Amazon US via AWD and FBA; domestic channel = Ghana retail. Change the export share in Inputs G05.
A4: Crude butter per jar (kg) | B4: =in_V02/1000*in_V03/(1-in_V04) -> 0.16904255 | J4: Channel | K4: Stays in Ghana | L4: Leaves Ghana
A5: Retail units per year | B5: =in_C01*1000*in_C12/c_crude_kg -> 354940.21 | J5: Amazon US | K5: =E29 -> 4.0264108 | L5: =F29 -> 10.963589
A6: Amazon units per year | B6: =c_units*in_G05 -> 301699.18 | J6: Ghana retail | K6: =E42 -> 5.37 | L6: =F42 -> 0.63
A7: Customs value per jar (FOB, at cost) | B7: =SUM(B11:B15) -> 2.0233191
A10: Export channel: Amazon US | B10: USD per jar | C10: % of price | D10: Share in Ghana | E10: Stays in Ghana | F10: Leaves Ghana | G10: Inputs used
A11: Crude shea butter (paid to women processors) | B11: =c_crude_kg*in_C02 -> 0.47331915 | C11: =B11/in_V01 -> 0.03157566 | D11: 1 | E11: =B11*D11 -> 0.47331915 | F11: =B11-E11 -> 0 | G11: C02, V02–V04
A12: Other ingredients | B12: =in_V05 -> 0.3 | C12: =B12/in_V01 -> 0.020013342 | D12: =1-in_V06 -> 0.3 | E12: =B12*D12 -> 0.09 | F12: =B12-E12 -> 0.21 | G12: V05, V06
A13: Packaging | B13: =in_V07 -> 0.7 | C13: =B13/in_V01 -> 0.046697799 | D13: =1-in_V08 -> 0.4 | E13: =B13*D13 -> 0.28 | F13: =B13-E13 -> 0.42 | G13: V07, V08
A14: Factory conversion in Tema | B14: =in_V09 -> 0.5 | C14: =B14/in_V01 -> 0.03335557 | D14: 1 | E14: =B14*D14 -> 0.5 | F14: =B14-E14 -> 0 | G14: V09
A15: Ghana port, handling, documents | B15: =in_V10 -> 0.05 | C15: =B15/in_V01 -> 0.003335557 | D15: 1 | E15: =B15*D15 -> 0.05 | F15: =B15-E15 -> 0 | G15: V10
A16: Ocean freight to US | B16: =in_V12/in_V11 -> 0.1375 | C16: =B16/in_V01 -> 0.0091727819 | D16: 0 | E16: =B16*D16 -> 0 | F16: =B16-E16 -> 0.1375 | G16: V11, V12
A17: US import duty and tariff | B17: =(in_V13+in_V14)*c_fob -> 0.20233191 | C17: =B17/in_V01 -> 0.013497793 | D17: 0 | E17: =B17*D17 -> 0 | F17: =B17-E17 -> 0.20233191 | G17: V13, V14
A18: US broker, drayage, trucking | B18: =in_V15 -> 0.1 | C18: =B18/in_V01 -> 0.0066711141 | D18: 0 | E18: =B18*D18 -> 0 | F18: =B18-E18 -> 0.1 | G18: V15
A19: Amazon AWD storage | B19: =in_V16*in_V18*in_V17 -> 0.024 | C19: =B19/in_V01 -> 0.0016010674 | D19: 0 | E19: =B19*D19 -> 0 | F19: =B19-E19 -> 0.024 | G19: V16–V18
A20: Amazon AWD processing | B20: =in_V20/in_V19 -> 0.11666667 | C20: =B20/in_V01 -> 0.0077829664 | D20: 0 | E20: =B20*D20 -> 0 | F20: =B20-E20 -> 0.11666667 | G20: V19, V20
A21: Amazon AWD transport to FBA | B21: =in_V21*in_V18 -> 0.035 | C21: =B21/in_V01 -> 0.0023348899 | D21: 0 | E21: =B21*D21 -> 0 | F21: =B21-E21 -> 0.035 | G21: V18, V21
A22: Amazon FBA fulfillment fee | B22: =in_V22 -> 5.2 | C22: =B22/in_V01 -> 0.34689793 | D22: 0 | E22: =B22*D22 -> 0 | F22: =B22-E22 -> 5.2 | G22: V22
A23: Amazon FBA storage (1 month) | B23: =in_V23*in_V18 -> 0.0195 | C23: =B23/in_V01 -> 0.0013008672 | D23: 0 | E23: =B23*D23 -> 0 | F23: =B23-E23 -> 0.0195 | G23: V18, V23
A24: Amazon referral fee | B24: =IF(in_V01<=10,in_V32,in_V24)*in_V01 -> 2.2485 | C24: =B24/in_V01 -> 0.15 | D24: 0 | E24: =B24*D24 -> 0 | F24: =B24-E24 -> 2.2485 | G24: V01, V24
A25: Amazon advertising | B25: =in_V25*in_V01 -> 1.7988 | C25: =B25/in_V01 -> 0.12 | D25: 0 | E25: =B25*D25 -> 0 | F25: =B25-E25 -> 1.7988 | G25: V25
A26: Returns and damages | B26: =in_V26*in_V01 -> 0.4497 | C26: =B26/in_V01 -> 0.03 | D26: 0 | E26: =B26*D26 -> 0 | F26: =B26-E26 -> 0.4497 | G26: V26
A27: Amazon Professional plan | B27: =IF(c_units_amz>0,in_V31*12/c_units_amz,0) -> 0.001590591 | C27: =B27/in_V01 -> 0.00010611014 | D27: 0 | E27: =B27*D27 -> 0 | F27: =B27-E27 -> 0.001590591 | G27: V31
A28: Brand contribution margin (Ghanaian company) | B28: =in_V01-SUM(B11:B27) -> 2.6330917 | C28: =B28/in_V01 -> 0.17565655 | D28: 1 | E28: =B28*D28 -> 2.6330917 | F28: =B28-E28 -> 0 | G28: Free Zone: 0% tax years 1–10
A29: Retail price | B29: =SUM(B11:B28) -> 14.99 | C29: =SUM(C11:C28) -> 1 | E29: =SUM(E11:E28) -> 4.0264108 | F29: =SUM(F11:F28) -> 10.963589
A30: Share of the retail price that stays in Ghana | E30: =E29/B29 -> 0.26860646
A31: Share captured by Amazon (fees, storage, ads, plan) | E31: =(SUM(B19:B25)+B27)/B29 -> 0.63002383
A33: Domestic channel: Ghana retail | B33: USD per jar | C33: % of price | D33: Share in Ghana | E33: Stays in Ghana | F33: Leaves Ghana | G33: Inputs used
A34: Crude shea butter (paid to women processors) | B34: =c_crude_kg*in_C02 -> 0.47331915 | C34: =B34/in_V27 -> 0.078886525 | D34: 1 | E34: =B34*D34 -> 0.47331915 | F34: =B34-E34 -> 0 | G34: C02, V02–V04
A35: Other ingredients | B35: =in_V05 -> 0.3 | C35: =B35/in_V27 -> 0.05 | D35: =1-in_V06 -> 0.3 | E35: =B35*D35 -> 0.09 | F35: =B35-E35 -> 0.21 | G35: V05, V06
A36: Packaging | B36: =in_V07 -> 0.7 | C36: =B36/in_V27 -> 0.11666667 | D36: =1-in_V08 -> 0.4 | E36: =B36*D36 -> 0.28 | F36: =B36-E36 -> 0.42 | G36: V07, V08
A37: Factory conversion in Tema | B37: =in_V09 -> 0.5 | C37: =B37/in_V27 -> 0.083333333 | D37: 1 | E37: =B37*D37 -> 0.5 | F37: =B37-E37 -> 0 | G37: V09
A38: Domestic distribution | B38: =in_V30 -> 0.2 | C38: =B38/in_V27 -> 0.033333333 | D38: 1 | E38: =B38*D38 -> 0.2 | F38: =B38-E38 -> 0 | G38: V30
A39: Retailer and distributor margin | B39: =in_V28*in_V27 -> 2.1 | C39: =B39/in_V27 -> 0.35 | D39: 1 | E39: =B39*D39 -> 2.1 | F39: =B39-E39 -> 0 | G39: V28
A40: VAT and levies | B40: =in_V27*in_V29/(1+in_V29) -> 1 | C40: =B40/in_V27 -> 0.16666667 | D40: 1 | E40: =B40*D40 -> 1 | F40: =B40-E40 -> 0 | G40: V29
A41: Brand contribution margin (Ghanaian company) | B41: =in_V27-SUM(B34:B40) -> 0.72668085 | C41: =B41/in_V27 -> 0.12111348 | D41: 1 | E41: =B41*D41 -> 0.72668085 | F41: =B41-E41 -> 0
A42: Retail price | B42: =SUM(B34:B41) -> 6 | C42: =SUM(C34:C41) -> 1 | E42: =SUM(E34:E41) -> 5.37 | F42: =SUM(F34:F41) -> 0.63
A43: Share of the retail price that stays in Ghana | E43: =E42/B42 -> 0.895
A45: Summary
...

Sheet Calc
A1: Derived quantities (formulas only)
A3: Quantity | B3: Name | C3: Value | D3: Formula logic
A4: Contribution margin per t crude butter, active | B4: c_margin | C4: =IF(in_C11=1,in_C03,in_C12*c_margin_vc+(1-in_C12)*in_C03) -> 5215.4542 | D4: C11 = 1 uses bulk benchmark C03; 2 blends value-chain margin (share C12) with bulk
A5: Value of one secured tonne of butter | B5: c_VST | C5: =(1-in_C05)*in_C04+in_C05*c_margin -> 2037.1363 | D5: Replaceable share pays premium C04; unreplaceable share loses margin
A6: Kernel needed | B6: c_kernel | C6: =in_C01/in_C13 -> 540.54054 | D6: t kernel per year
A7: Sourcing area | B7: c_catch | C7: =c_kernel*1000/(in_R05*in_F06) -> 6756.7568 | D7: ha = kernel kg ÷ (kg per tree × trees per ha)
A8: Annual contribution margin | B8: c_annual | C8: =in_C01*c_margin -> 1043090.8
A9: Daily contribution margin | B9: c_daily | C9: =c_annual/in_C14 -> 4172.3634
A10: Hourly contribution margin | B10: c_hourly | C10: =c_daily/in_C09 -> 260.77271
A11: Outage hours inside operating shifts | B11: c_out_hrs | C11: =in_H08*in_C09/24*in_C14/365 -> 114.15525 | D11: Outages spread over the year; only those in shifts on operating days count
A12: Average plant load | B12: c_avg_kw | C12: =in_C08*1000/(in_C14*in_C09) -> 62.5 | D12: kW
A13: Lost production margin from outages | B13: c_out_prod | C13: =c_out_hrs*c_hourly*in_C10 -> 14884.287
A14: Spoilage and restart from outages | B14: c_out_spoil | C14: =c_out_hrs/in_H10*in_E07 -> 19025.875
A15: Baseline outage cost per year | B15: c_out_cost | C15: =c_out_prod+c_out_spoil -> 33910.162 | D15: Lost margin not recovered + spoilage per outage event
A16: Outage cost avoided by battery | B16: c_bat_avoid | C16: =in_E14*(c_out_spoil+c_out_prod*MIN(1,in_E06a/c_avg_kw)) -> 18319.233 | D16: Critical loads protected; production continues only in proportion to load covered
A17: Outage cost avoided by genset | B17: c_gen_avoid | C17: =c_out_spoil+c_out_prod*MIN(1,in_E25/c_avg_kw) -> 26170.333
A18: Outage cost as share of sales | B18: c_out_pct | C18: =IF(c_sales>0,c_out_cost/c_sales,0) -> 0.0060926854 | D18: Check against 0–10% band reported by Ghanaian firms (WBES)
A19: Damage share at flood depth without measures | B19: c_D0 | C19: =INDEX(CHOOSE(in_H09,Hazards!$B$5:$B$10,Hazards!$C$5:$C$10),MATCH(MIN(MAX(in_H06,0),3),Hazards!$A$5:$A$10,1))+IF(MATCH(MIN(MAX(in_H06,0),3),Hazards!$A$5:$A$10,1)=6,0,(INDEX(CHOOSE(in_H09,Hazards!$B$5:$B$10,Hazards!$C$5:$C$10),MIN(MATCH(MIN(MAX(in_H06,0),3),Hazards!$A$5:$A$10,1)+1,6))-INDEX(CHOOSE(in_H09,Hazards!$B$5:$B$10,Hazards!$C$5:$C$10),MATCH(MIN(MAX(in_H06,0),3),Hazards!$A$5:$A$10,1)))*(MIN(MAX(in_H06,0),3)-INDEX(Hazards!$A$5:$A$10,MATCH(MIN(MAX(in_H06,0),3),Hazards!$A$5:$A$10,1)))/(INDEX(Hazards!$A$5:$A$10,MIN(MATCH(MIN(MAX(in_H06,0),3),Hazards!$A$5:$A$10,1)+1,6))-INDEX(Hazards!$A$5:$A$10,MATCH(MIN(MAX(in_H06,0),3),Hazards!$A$5:$A$10,1)))) -> 0.0627 | D19: Interpolated on Hazards curve
A20: Damage share at depth with measures | B20: c_D1 | C20: =INDEX(CHOOSE(in_H09,Hazards!$B$5:$B$10,Hazards!$C$5:$C$10),MATCH(MIN(MAX(in_D07,0),3),Hazards!$A$5:$A$10,1))+IF(MATCH(MIN(MAX(in_D07,0),3),Hazards!$A$5:$A$10,1)=6,0,(INDEX(CHOOSE(in_H09,Hazards!$B$5:$B$10,Hazards!$C$5:$C$10),MIN(MATCH(MIN(MAX(in_D07,0),3),Hazards!$A$5:$A$10,1)+1,6))-INDEX(CHOOSE(in_H09,Hazards!$B$5:$B$10,Hazards!$C$5:$C$10),MATCH(MIN(MAX(in_D07,0),3),Hazards!$A$5:$A$10,1)))*(MIN(MAX(in_D07,0),3)-INDEX(Hazards!$A$5:$A$10,MATCH(MIN(MAX(in_D07,0),3),Hazards!$A$5:$A$10,1)))/(INDEX(Hazards!$A$5:$A$10,MIN(MATCH(MIN(MAX(in_D07,0),3),Hazards!$A$5:$A$10,1)+1,6))-INDEX(Hazards!$A$5:$A$10,MATCH(MIN(MAX(in_D07,0),3),Hazards!$A$5:$A$10,1)))) -> 0.01254
A21: Property loss per flood, without | B21: c_prop0 | C21: =in_C07*c_D0 -> 112860
A22: Property loss per flood, with measures | B22: c_prop1 | C22: =in_C07*c_D1 -> 22572
A23: Downtime loss per flood, without | B23: c_bi0 | C23: =in_H07*c_daily*in_C10 -> 10430.908
A24: Downtime loss per flood, with measures | B24: c_bi1 | C24: =in_D09*c_daily*in_C10 -> 2086.1817
A25: Total loss per flood, without | B25: c_floss0 | C25: =c_prop0+c_bi0 -> 123290.91
A26: Total loss per flood, with measures | B26: c_floss1 | C26: =c_prop1+c_bi1 -> 24658.182
A27: Insurance recovery per flood, without works | B27: c_rec0 | C27: =in_N04*(MAX(0,c_prop0-MAX(in_N03a*c_prop0,in_N03b))+c_bi0) -> 78403.436 | D27: After deductible and under-insurance
A28: Insurance recovery per flood, with works | B28: c_rec1 | C28: =in_N04*(MAX(0,c_prop1-MAX(in_N03a*c_prop1,in_N03b))+c_bi1) -> 10260.727
A29: Annual insurance premium | B29: c_premium | C29: =in_N01*in_C07+in_N02*c_annual -> 7629.2725 | D29: Property incl. flood + business interruption on contribution margin
A30: Flood works capex | B30: c_flood_cap | C30: =in_D02*in_D01*(1+in_D03)+in_D05*in_D04+in_D06 -> 117325
A31: PV capex | B31: c_pv_cap | C31: =in_E09*in_E01 -> 100000
A32: Battery nameplate | B32: c_bat_kwh | C32: =in_E06a*in_E06b/(in_E16*in_E17*in_E18) -> 208.33333 | D32: kWh
A33: Battery capex incl. islanding | B33: c_bat_cap | C33: =c_bat_kwh*in_E05+in_E13 -> 82916.667
A34: Genset size | B34: c_gen_kva | C34: =in_E25*in_E19 -> 46.8 | D34: kVA
A35: Genset capex | B35: c_gen_cap | C35: =c_gen_kva*in_E10 -> 16192.8
A36: Genset fuel per year | B36: c_gen_fuel | C36: =c_out_hrs*MIN(in_E25,c_avg_kw)*in_E04 -> 1815.0685
A37: Irrigation capex incl. dry holes | B37: c_irr_cap | C37: =in_I03*(in_I01+(1/in_I02-1)*in_I08) -> 120577.78
A38: Apiary share of sourcing area | B38: c_api_share | C38: =MIN(1,in_A08/in_A10*PI()*in_A11^2*100/c_catch) -> 0.23247786 | D38: Apiaries × π r² (km² → ha) ÷ sourcing area
A39: Beeswax harvested | B39: c_wax | C39: =in_A08*in_A04*in_A02*in_A03 -> 104 | D39: kg per year
A40: Regeneration area planted | B40: c_regen_ha | C40: =in_R07/in_R09 -> 100 | D40: ha
A41: Share of supply served by stoves | B41: c_stove_served | C41: =MIN(1,in_S05*in_S06/in_C01) -> 1
...

Sheet Supply
A1: Supply model: tonnes of crude butter and the value of supply lost (USD)
A2: Loss each year = (structural deficit + poor-year shortfall) × value of a secured tonne. Options cut the decline rate d, cut the poor-year loss (reduction), or add new supply.
A3: Year | D3: 0 | E3: 1 | F3: 2 | G3: 3 | H3: 4 | I3: 5 | J3: 6 | K3: 7 | L3: 8 | M3: 9 | N3: 10 | O3: 11 | P3: 12 | Q3: 13 | R3: 14 | S3: 15 | T3: 16 | U3: 17 | V3: 18 | W3: 19 | X3: 20 | Y3: 21 | Z3: 22 | AA3: 23 | AB3: 24 | AC3: 25 | AD3: 26 | AE3: 27 | AF3: 28 | AG3: 29 | AH3: 30
A5: Baseline (no options)
A6: Supply available (t butter) | D6: =IF(D$3=0,0,in_C01*in_C06*(1-in_H04)^D$3) -> 0 | E6: =IF(E$3=0,0,in_C01*in_C06*(1-in_H04)^E$3) -> 246.25 | F6: =IF(F$3=0,0,in_C01*in_C06*(1-in_H04)^F$3) -> 242.55625 | G6: =IF(G$3=0,0,in_C01*in_C06*(1-in_H04)^G$3) -> 238.91791 | H6: =IF(H$3=0,0,in_C01*in_C06*(1-in_H04)^H$3) -> 235.33414 | I6: =IF(I$3=0,0,in_C01*in_C06*(1-in_H04)^I$3) -> 231.80413 | J6: =IF(J$3=0,0,in_C01*in_C06*(1-in_H04)^J$3) -> 228.32706 | K6: =IF(K$3=0,0,in_C01*in_C06*(1-in_H04)^K$3) -> 224.90216 | ... AH6: =IF(AH$3=0,0,in_C01*in_C06*(1-in_H04)^AH$3) -> 158.86452
A7: Value of supply lost (USD) | D7: =IF(D$3=0,0,(MAX(0,in_C01-D6)+in_H01*in_H02*MIN(in_C01,D6))*c_VST) -> 0 | E7: =IF(E$3=0,0,(MAX(0,in_C01-E6)+in_H01*in_H02*MIN(in_C01,E6))*c_VST) -> 36668.453 | F7: =IF(F$3=0,0,(MAX(0,in_C01-F6)+in_H01*in_H02*MIN(in_C01,F6))*c_VST) -> 36668.453 | G7: =IF(G$3=0,0,(MAX(0,in_C01-G6)+in_H01*in_H02*MIN(in_C01,G6))*c_VST) -> 36668.453 | H7: =IF(H$3=0,0,(MAX(0,in_C01-H6)+in_H01*in_H02*MIN(in_C01,H6))*c_VST) -> 36668.453 | I7: =IF(I$3=0,0,(MAX(0,in_C01-I6)+in_H01*in_H02*MIN(in_C01,I6))*c_VST) -> 36668.453 | J7: =IF(J$3=0,0,(MAX(0,in_C01-J6)+in_H01*in_H02*MIN(in_C01,J6))*c_VST) -> 36668.453 | K7: =IF(K$3=0,0,(MAX(0,in_C01-K6)+in_H01*in_H02*MIN(in_C01,K6))*c_VST) -> 36668.453 | ... AH7: =IF(AH$3=0,0,(MAX(0,in_C01-AH6)+in_H01*in_H02*MIN(in_C01,AH6))*c_VST) -> 112925.15
A9: 1 Solar irrigation
A10: Decline rate d | B10: =in_H04 -> 0.015
A11: Poor-year loss reduction | B11: =in_P01*in_I05 -> 0.025
A12: New supply added (t butter) | D12: =IF(D$3=0,0,0) -> 0 | E12: =IF(E$3=0,0,0) -> 0 | F12: =IF(F$3=0,0,0) -> 0 | G12: =IF(G$3=0,0,0) -> 0 | H12: =IF(H$3=0,0,0) -> 0 | I12: =IF(I$3=0,0,0) -> 0 | J12: =IF(J$3=0,0,0) -> 0 | K12: =IF(K$3=0,0,0) -> 0 | ... AH12: =IF(AH$3=0,0,0) -> 0
A13: Supply available (t butter) | D13: =IF(D$3=0,0,in_C01*in_C06*(1-$B$10)^D$3+D12) -> 0 | E13: =IF(E$3=0,0,in_C01*in_C06*(1-$B$10)^E$3+E12) -> 246.25 | F13: =IF(F$3=0,0,in_C01*in_C06*(1-$B$10)^F$3+F12) -> 242.55625 | G13: =IF(G$3=0,0,in_C01*in_C06*(1-$B$10)^G$3+G12) -> 238.91791 | H13: =IF(H$3=0,0,in_C01*in_C06*(1-$B$10)^H$3+H12) -> 235.33414 | I13: =IF(I$3=0,0,in_C01*in_C06*(1-$B$10)^I$3+I12) -> 231.80413 | J13: =IF(J$3=0,0,in_C01*in_C06*(1-$B$10)^J$3+J12) -> 228.32706 | K13: =IF(K$3=0,0,in_C01*in_C06*(1-$B$10)^K$3+K12) -> 224.90216 | ... AH13: =IF(AH$3=0,0,in_C01*in_C06*(1-$B$10)^AH$3+AH12) -> 158.86452
A14: Value of supply lost (USD) | D14: =IF(D$3=0,0,(MAX(0,in_C01-D13)+in_H01*in_H02*MIN(in_C01,D13)*(1-$B$11))*c_VST) -> 0 | E14: =IF(E$3=0,0,(MAX(0,in_C01-E13)+in_H01*in_H02*MIN(in_C01,E13)*(1-$B$11))*c_VST) -> 35751.741 | F14: =IF(F$3=0,0,(MAX(0,in_C01-F13)+in_H01*in_H02*MIN(in_C01,F13)*(1-$B$11))*c_VST) -> 35751.741 | G14: =IF(G$3=0,0,(MAX(0,in_C01-G13)+in_H01*in_H02*MIN(in_C01,G13)*(1-$B$11))*c_VST) -> 35751.741 | H14: =IF(H$3=0,0,(MAX(0,in_C01-H13)+in_H01*in_H02*MIN(in_C01,H13)*(1-$B$11))*c_VST) -> 35751.741 | I14: =IF(I$3=0,0,(MAX(0,in_C01-I13)+in_H01*in_H02*MIN(in_C01,I13)*(1-$B$11))*c_VST) -> 35751.741 | J14: =IF(J$3=0,0,(MAX(0,in_C01-J13)+in_H01*in_H02*MIN(in_C01,J13)*(1-$B$11))*c_VST) -> 35751.741 | K14: =IF(K$3=0,0,(MAX(0,in_C01-K13)+in_H01*in_H02*MIN(in_C01,K13)*(1-$B$11))*c_VST) -> 35751.741 | ... AH14: =IF(AH$3=0,0,(MAX(0,in_C01-AH13)+in_H01*in_H02*MIN(in_C01,AH13)*(1-$B$11))*c_VST) -> 112196.99
A15: Supply benefit vs baseline (USD) | D15: =D7-D14 -> 0 | E15: =E7-E14 -> 916.71132 | F15: =F7-F14 -> 916.71132 | G15: =G7-G14 -> 916.71132 | H15: =H7-H14 -> 916.71132 | I15: =I7-I14 -> 916.71132 | J15: =J7-J14 -> 916.71132 | K15: =K7-K14 -> 916.71132 | ... AH15: =AH7-AH14 -> 728.16453
A16: 2 Apiaries
A17: Decline rate d | B17: =in_H04 -> 0.015
A18: Poor-year loss reduction | B18: =c_api_share*in_A07*in_H03 -> 0.0034871678
A19: New supply added (t butter) | D19: =IF(D$3=0,0,in_A06*c_api_share*D6) -> 0 | E19: =IF(E$3=0,0,in_A06*c_api_share*E6) -> 0 | F19: =IF(F$3=0,0,in_A06*c_api_share*F6) -> 0 | G19: =IF(G$3=0,0,in_A06*c_api_share*G6) -> 0 | H19: =IF(H$3=0,0,in_A06*c_api_share*H6) -> 0 | I19: =IF(I$3=0,0,in_A06*c_api_share*I6) -> 0 | J19: =IF(J$3=0,0,in_A06*c_api_share*J6) -> 0 | K19: =IF(K$3=0,0,in_A06*c_api_share*K6) -> 0 | ... AH19: =IF(AH$3=0,0,in_A06*c_api_share*AH6) -> 0
A20: Supply available (t butter) | D20: =IF(D$3=0,0,in_C01*in_C06*(1-$B$17)^D$3+D19) -> 0 | E20: =IF(E$3=0,0,in_C01*in_C06*(1-$B$17)^E$3+E19) -> 246.25 | F20: =IF(F$3=0,0,in_C01*in_C06*(1-$B$17)^F$3+F19) -> 242.55625 | G20: =IF(G$3=0,0,in_C01*in_C06*(1-$B$17)^G$3+G19) -> 238.91791 | H20: =IF(H$3=0,0,in_C01*in_C06*(1-$B$17)^H$3+H19) -> 235.33414 | I20: =IF(I$3=0,0,in_C01*in_C06*(1-$B$17)^I$3+I19) -> 231.80413 | J20: =IF(J$3=0,0,in_C01*in_C06*(1-$B$17)^J$3+J19) -> 228.32706 | K20: =IF(K$3=0,0,in_C01*in_C06*(1-$B$17)^K$3+K19) -> 224.90216 | ... AH20: =IF(AH$3=0,0,in_C01*in_C06*(1-$B$17)^AH$3+AH19) -> 158.86452
A21: Value of supply lost (USD) | D21: =IF(D$3=0,0,(MAX(0,in_C01-D20)+in_H01*in_H02*MIN(in_C01,D20)*(1-$B$18))*c_VST) -> 0 | E21: =IF(E$3=0,0,(MAX(0,in_C01-E20)+in_H01*in_H02*MIN(in_C01,E20)*(1-$B$18))*c_VST) -> 36540.584 | F21: =IF(F$3=0,0,(MAX(0,in_C01-F20)+in_H01*in_H02*MIN(in_C01,F20)*(1-$B$18))*c_VST) -> 36540.584 | G21: =IF(G$3=0,0,(MAX(0,in_C01-G20)+in_H01*in_H02*MIN(in_C01,G20)*(1-$B$18))*c_VST) -> 36540.584 | H21: =IF(H$3=0,0,(MAX(0,in_C01-H20)+in_H01*in_H02*MIN(in_C01,H20)*(1-$B$18))*c_VST) -> 36540.584 | I21: =IF(I$3=0,0,(MAX(0,in_C01-I20)+in_H01*in_H02*MIN(in_C01,I20)*(1-$B$18))*c_VST) -> 36540.584 | J21: =IF(J$3=0,0,(MAX(0,in_C01-J20)+in_H01*in_H02*MIN(in_C01,J20)*(1-$B$18))*c_VST) -> 36540.584 | K21: =IF(K$3=0,0,(MAX(0,in_C01-K20)+in_H01*in_H02*MIN(in_C01,K20)*(1-$B$18))*c_VST) -> 36540.584 | ... AH21: =IF(AH$3=0,0,(MAX(0,in_C01-AH20)+in_H01*in_H02*MIN(in_C01,AH20)*(1-$B$18))*c_VST) -> 112823.58
A22: Supply benefit vs baseline (USD) | D22: =D7-D21 -> 0 | E22: =E7-E21 -> 127.86905 | F22: =F7-F21 -> 127.86905 | G22: =G7-G21 -> 127.86905 | H22: =H7-H21 -> 127.86905 | I22: =I7-I21 -> 127.86905 | J22: =J7-J21 -> 127.86905 | K22: =K7-K21 -> 127.86905 | ... AH22: =AH7-AH21 -> 101.56928
A23: 3 Regeneration
A24: Decline rate d | B24: =in_H04 -> 0.015
A25: Poor-year loss reduction | B25: 0
A26: New supply added (t butter) | D26: =IF(D$3=0,0,in_R07*in_R03*in_R05/1000*in_C13*MIN(1,MAX(0,(D$3-in_R04a)/(in_R04b-in_R04a)))*in_R06) -> 0 | E26: =IF(E$3=0,0,in_R07*in_R03*in_R05/1000*in_C13*MIN(1,MAX(0,(E$3-in_R04a)/(in_R04b-in_R04a)))*in_R06) -> 0 | F26: =IF(F$3=0,0,in_R07*in_R03*in_R05/1000*in_C13*MIN(1,MAX(0,(F$3-in_R04a)/(in_R04b-in_R04a)))*in_R06) -> 0 | G26: =IF(G$3=0,0,in_R07*in_R03*in_R05/1000*in_C13*MIN(1,MAX(0,(G$3-in_R04a)/(in_R04b-in_R04a)))*in_R06) -> 0 | H26: =IF(H$3=0,0,in_R07*in_R03*in_R05/1000*in_C13*MIN(1,MAX(0,(H$3-in_R04a)/(in_R04b-in_R04a)))*in_R06) -> 0 | I26: =IF(I$3=0,0,in_R07*in_R03*in_R05/1000*in_C13*MIN(1,MAX(0,(I$3-in_R04a)/(in_R04b-in_R04a)))*in_R06) -> 0 | J26: =IF(J$3=0,0,in_R07*in_R03*in_R05/1000*in_C13*MIN(1,MAX(0,(J$3-in_R04a)/(in_R04b-in_R04a)))*in_R06) -> 0 | K26: =IF(K$3=0,0,in_R07*in_R03*in_R05/1000*in_C13*MIN(1,MAX(0,(K$3-in_R04a)/(in_R04b-in_R04a)))*in_R06) -> 0.296 | ... AH26: =IF(AH$3=0,0,in_R07*in_R03*in_R05/1000*in_C13*MIN(1,MAX(0,(AH$3-in_R04a)/(in_R04b-in_R04a)))*in_R06) -> 2.368
A27: Supply available (t butter) | D27: =IF(D$3=0,0,in_C01*in_C06*(1-$B$24)^D$3+D26) -> 0 | E27: =IF(E$3=0,0,in_C01*in_C06*(1-$B$24)^E$3+E26) -> 246.25 | F27: =IF(F$3=0,0,in_C01*in_C06*(1-$B$24)^F$3+F26) -> 242.55625 | G27: =IF(G$3=0,0,in_C01*in_C06*(1-$B$24)^G$3+G26) -> 238.91791 | H27: =IF(H$3=0,0,in_C01*in_C06*(1-$B$24)^H$3+H26) -> 235.33414 | I27: =IF(I$3=0,0,in_C01*in_C06*(1-$B$24)^I$3+I26) -> 231.80413 | J27: =IF(J$3=0,0,in_C01*in_C06*(1-$B$24)^J$3+J26) -> 228.32706 | K27: =IF(K$3=0,0,in_C01*in_C06*(1-$B$24)^K$3+K26) -> 225.19816 | ... AH27: =IF(AH$3=0,0,in_C01*in_C06*(1-$B$24)^AH$3+AH26) -> 161.23252
A28: Value of supply lost (USD) | D28: =IF(D$3=0,0,(MAX(0,in_C01-D27)+in_H01*in_H02*MIN(in_C01,D27)*(1-$B$25))*c_VST) -> 0 | E28: =IF(E$3=0,0,(MAX(0,in_C01-E27)+in_H01*in_H02*MIN(in_C01,E27)*(1-$B$25))*c_VST) -> 36668.453 | F28: =IF(F$3=0,0,(MAX(0,in_C01-F27)+in_H01*in_H02*MIN(in_C01,F27)*(1-$B$25))*c_VST) -> 36668.453 | G28: =IF(G$3=0,0,(MAX(0,in_C01-G27)+in_H01*in_H02*MIN(in_C01,G27)*(1-$B$25))*c_VST) -> 36668.453 | H28: =IF(H$3=0,0,(MAX(0,in_C01-H27)+in_H01*in_H02*MIN(in_C01,H27)*(1-$B$25))*c_VST) -> 36668.453 | I28: =IF(I$3=0,0,(MAX(0,in_C01-I27)+in_H01*in_H02*MIN(in_C01,I27)*(1-$B$25))*c_VST) -> 36668.453 | J28: =IF(J$3=0,0,(MAX(0,in_C01-J27)+in_H01*in_H02*MIN(in_C01,J27)*(1-$B$25))*c_VST) -> 36668.453 | K28: =IF(K$3=0,0,(MAX(0,in_C01-K27)+in_H01*in_H02*MIN(in_C01,K27)*(1-$B$25))*c_VST) -> 36668.453 | ... AH28: =IF(AH$3=0,0,(MAX(0,in_C01-AH27)+in_H01*in_H02*MIN(in_C01,AH27)*(1-$B$25))*c_VST) -> 108535.37
A29: Supply benefit vs baseline (USD) | D29: =D7-D28 -> 0 | E29: =E7-E28 -> 0 | F29: =F7-F28 -> 0 | G29: =G7-G28 -> 0 | H29: =H7-H28 -> 0 | I29: =I7-I28 -> 0 | J29: =J7-J28 -> 0 | K29: =K7-K28 -> 0 | ... AH29: =AH7-AH28 -> 4389.7842
A30: 5 Processing stoves
A31: Decline rate d | B31: =in_H04-in_S04 -> 0.0135
A32: Poor-year loss reduction | B32: =c_stove_served*in_I05 -> 0.05
A33: New supply added (t butter) | D33: =IF(D$3=0,0,0) -> 0 | E33: =IF(E$3=0,0,0) -> 0 | F33: =IF(F$3=0,0,0) -> 0 | G33: =IF(G$3=0,0,0) -> 0 | H33: =IF(H$3=0,0,0) -> 0 | I33: =IF(I$3=0,0,0) -> 0 | J33: =IF(J$3=0,0,0) -> 0 | K33: =IF(K$3=0,0,0) -> 0 | ... AH33: =IF(AH$3=0,0,0) -> 0
A34: Supply available (t butter) | D34: =IF(D$3=0,0,in_C01*in_C06*(1-$B$31)^D$3+D33) -> 0 | E34: =IF(E$3=0,0,in_C01*in_C06*(1-$B$31)^E$3+E33) -> 246.625 | F34: =IF(F$3=0,0,in_C01*in_C06*(1-$B$31)^F$3+F33) -> 243.29556 | G34: =IF(G$3=0,0,in_C01*in_C06*(1-$B$31)^G$3+G33) -> 240.01107 | H34: =IF(H$3=0,0,in_C01*in_C06*(1-$B$31)^H$3+H33) -> 236.77092 | I34: =IF(I$3=0,0,in_C01*in_C06*(1-$B$31)^I$3+I33) -> 233.57452 | J34: =IF(J$3=0,0,in_C01*in_C06*(1-$B$31)^J$3+J33) -> 230.42126 | K34: =IF(K$3=0,0,in_C01*in_C06*(1-$B$31)^K$3+K33) -> 227.31057 | ... AH34: =IF(AH$3=0,0,in_C01*in_C06*(1-$B$31)^AH$3+AH33) -> 166.28486
A35: Value of supply lost (USD) | D35: =IF(D$3=0,0,(MAX(0,in_C01-D34)+in_H01*in_H02*MIN(in_C01,D34)*(1-$B$32))*c_VST) -> 0 | E35: =IF(E$3=0,0,(MAX(0,in_C01-E34)+in_H01*in_H02*MIN(in_C01,E34)*(1-$B$32))*c_VST) -> 34835.03 | F35: =IF(F$3=0,0,(MAX(0,in_C01-F34)+in_H01*in_H02*MIN(in_C01,F34)*(1-$B$32))*c_VST) -> 34835.03 | G35: =IF(G$3=0,0,(MAX(0,in_C01-G34)+in_H01*in_H02*MIN(in_C01,G34)*(1-$B$32))*c_VST) -> 34835.03 | H35: =IF(H$3=0,0,(MAX(0,in_C01-H34)+in_H01*in_H02*MIN(in_C01,H34)*(1-$B$32))*c_VST) -> 34835.03 | I35: =IF(I$3=0,0,(MAX(0,in_C01-I34)+in_H01*in_H02*MIN(in_C01,I34)*(1-$B$32))*c_VST) -> 34835.03 | J35: =IF(J$3=0,0,(MAX(0,in_C01-J34)+in_H01*in_H02*MIN(in_C01,J34)*(1-$B$32))*c_VST) -> 34835.03 | K35: =IF(K$3=0,0,(MAX(0,in_C01-K34)+in_H01*in_H02*MIN(in_C01,K34)*(1-$B$32))*c_VST) -> 34835.03 | ... AH35: =IF(AH$3=0,0,(MAX(0,in_C01-AH34)+in_H01*in_H02*MIN(in_C01,AH34)*(1-$B$32))*c_VST) -> 97645.034
A36: Supply benefit vs baseline (USD) | D36: =D7-D35 -> 0 | E36: =E7-E35 -> 1833.4226 | F36: =F7-F35 -> 1833.4226 | G36: =G7-G35 -> 1833.4226 | H36: =H7-H35 -> 1833.4226 | I36: =I7-I35 -> 1833.4226 | J36: =J7-J35 -> 1833.4226 | K36: =K7-K35 -> 1833.4226 | ... AH36: =AH7-AH35 -> 15280.119
A37: 8 Mango substitution hedge
A38: Decline rate d | B38: =in_H04 -> 0.015
A39: Poor-year loss reduction | B39: =c_sub_t/(in_H02*in_C01) -> 0.11666667
A40: New supply added (t butter) | D40: =IF(D$3=0,0,0) -> 0 | E40: =IF(E$3=0,0,0) -> 0 | F40: =IF(F$3=0,0,0) -> 0 | G40: =IF(G$3=0,0,0) -> 0 | H40: =IF(H$3=0,0,0) -> 0 | I40: =IF(I$3=0,0,0) -> 0 | J40: =IF(J$3=0,0,0) -> 0 | K40: =IF(K$3=0,0,0) -> 0 | ... AH40: =IF(AH$3=0,0,0) -> 0
A41: Supply available (t butter) | D41: =IF(D$3=0,0,in_C01*in_C06*(1-$B$38)^D$3+D40) -> 0 | E41: =IF(E$3=0,0,in_C01*in_C06*(1-$B$38)^E$3+E40) -> 246.25 | F41: =IF(F$3=0,0,in_C01*in_C06*(1-$B$38)^F$3+F40) -> 242.55625 | G41: =IF(G$3=0,0,in_C01*in_C06*(1-$B$38)^G$3+G40) -> 238.91791 | H41: =IF(H$3=0,0,in_C01*in_C06*(1-$B$38)^H$3+H40) -> 235.33414 | I41: =IF(I$3=0,0,in_C01*in_C06*(1-$B$38)^I$3+I40) -> 231.80413 | J41: =IF(J$3=0,0,in_C01*in_C06*(1-$B$38)^J$3+J40) -> 228.32706 | K41: =IF(K$3=0,0,in_C01*in_C06*(1-$B$38)^K$3+K40) -> 224.90216 | ... AH41: =IF(AH$3=0,0,in_C01*in_C06*(1-$B$38)^AH$3+AH40) -> 158.86452
A42: Value of supply lost (USD) | D42: =IF(D$3=0,0,(MAX(0,in_C01-D41)+in_H01*in_H02*MIN(in_C01,D41)*(1-$B$39))*c_VST) -> 0 | E42: =IF(E$3=0,0,(MAX(0,in_C01-E41)+in_H01*in_H02*MIN(in_C01,E41)*(1-$B$39))*c_VST) -> 32390.467 | F42: =IF(F$3=0,0,(MAX(0,in_C01-F41)+in_H01*in_H02*MIN(in_C01,F41)*(1-$B$39))*c_VST) -> 32390.467 | G42: =IF(G$3=0,0,(MAX(0,in_C01-G41)+in_H01*in_H02*MIN(in_C01,G41)*(1-$B$39))*c_VST) -> 32390.467 | H42: =IF(H$3=0,0,(MAX(0,in_C01-H41)+in_H01*in_H02*MIN(in_C01,H41)*(1-$B$39))*c_VST) -> 32390.467 | I42: =IF(I$3=0,0,(MAX(0,in_C01-I41)+in_H01*in_H02*MIN(in_C01,I41)*(1-$B$39))*c_VST) -> 32390.467 | J42: =IF(J$3=0,0,(MAX(0,in_C01-J41)+in_H01*in_H02*MIN(in_C01,J41)*(1-$B$39))*c_VST) -> 32390.467 | K42: =IF(K$3=0,0,(MAX(0,in_C01-K41)+in_H01*in_H02*MIN(in_C01,K41)*(1-$B$39))*c_VST) -> 32390.467 | ... AH42: =IF(AH$3=0,0,(MAX(0,in_C01-AH41)+in_H01*in_H02*MIN(in_C01,AH41)*(1-$B$39))*c_VST) -> 109527.05
...

Sheet Engine
A1: Factory cash flows by option (USD, constant 2026 dollars)
A2: FCF = (supply benefit + other benefit − opex) − capex − tax, set to zero after the option's horizon. Free Zone tax: 0% to year G04a, then export/domestic blend.
A3: Year | C3: NPV / total | D3: 0 | E3: 1 | F3: 2 | G3: 3 | H3: 4 | I3: 5 | J3: 6 | K3: 7 | L3: 8 | M3: 9 | N3: 10 | O3: 11 | P3: 12 | Q3: 13 | R3: 14 | S3: 15 | T3: 16 | U3: 17 | V3: 18 | W3: 19 | X3: 20 | Y3: 21 | Z3: 22 | AA3: 23 | AB3: 24 | AC3: 25 | AD3: 26 | AE3: 27 | AF3: 28 | AG3: 29 | AH3: 30
A4: Tax rate | D4: =IF(D$3<=in_G04a,0,in_G05*in_G04b+(1-in_G05)*in_G04c) -> 0 | E4: =IF(E$3<=in_G04a,0,in_G05*in_G04b+(1-in_G05)*in_G04c) -> 0 | F4: =IF(F$3<=in_G04a,0,in_G05*in_G04b+(1-in_G05)*in_G04c) -> 0 | G4: =IF(G$3<=in_G04a,0,in_G05*in_G04b+(1-in_G05)*in_G04c) -> 0 | H4: =IF(H$3<=in_G04a,0,in_G05*in_G04b+(1-in_G05)*in_G04c) -> 0 | I4: =IF(I$3<=in_G04a,0,in_G05*in_G04b+(1-in_G05)*in_G04c) -> 0 | J4: =IF(J$3<=in_G04a,0,in_G05*in_G04b+(1-in_G05)*in_G04c) -> 0 | K4: =IF(K$3<=in_G04a,0,in_G05*in_G04b+(1-in_G05)*in_G04c) -> 0 | ... AH4: =IF(AH$3<=in_G04a,0,in_G05*in_G04b+(1-in_G05)*in_G04c) -> 0.165
A5: Discount factor | D5: =1/(1+in_G01)^D$3 -> 1 | E5: =1/(1+in_G01)^E$3 -> 0.88495575 | F5: =1/(1+in_G01)^F$3 -> 0.78314668 | G5: =1/(1+in_G01)^G$3 -> 0.69305016 | H5: =1/(1+in_G01)^H$3 -> 0.61331873 | I5: =1/(1+in_G01)^I$3 -> 0.54275994 | J5: =1/(1+in_G01)^J$3 -> 0.48031853 | K5: =1/(1+in_G01)^K$3 -> 0.42506064 | ... AH5: =1/(1+in_G01)^AH$3 -> 0.025565053
A7: 1 Solar irrigation (nurseries + gardens) | B7: Horizon | C7: =in_G02a -> 20
